<?xml version="1.0"?>
<robot xmlns:xacro="http://ros.org/wiki/xacro" >
   <xacro:include filename="$(find sara_description)/urdf/wheels_v1/wheels.gazebo.xacro" />
  <xacro:macro name="sara_wheels_v1" params="name parent" >
  <!-- Front_Wheels -->
  <xacro:macro name="front_wheel" params="prefix y_reflect x_reflect x_axis_rotation">
      <link name="${prefix}_wheel">
      </link>
      <joint name="base_to_${prefix}_wheel" type="continuous">
          <parent link="base_link"/>
          <child link="${prefix}_wheel"/>
          <axis xyz="0 0 1"/>
          <origin xyz="${y_reflect * 0.2056310} ${x_reflect * 0.22735} -0.06" rpy=" ${x_axis_rotation * 1.57079632679} 0 0"/>
      </joint>
   </xacro:macro>

   <!-- rear_Wheels -->
  <xacro:macro name="rear_wheel" params="prefix y_reflect x_reflect x_axis_rotation">
      <link name="${prefix}_wheel">
      </link>
      <joint name="base_to_${prefix}_wheel" type="continuous">
          <parent link="base_link"/>
          <child link="${prefix}_wheel"/>
          <axis xyz="0 0 1"/>
          <origin xyz="${y_reflect * 0.255631} ${x_reflect * 0.22735} -0.06" rpy=" ${x_axis_rotation * 1.57079632679} 0 0"/>
      </joint>
   </xacro:macro>


   <xacro:front_wheel prefix="front_left" y_reflect="1" x_reflect="1" x_axis_rotation="-1"/>
   <xacro:front_wheel prefix="front_right" y_reflect="1" x_reflect="-1" x_axis_rotation="1"/>
   <xacro:rear_wheel prefix="rear_left" y_reflect="-1" x_reflect="1" x_axis_rotation="-1"/>
   <xacro:rear_wheel prefix="rear_right" y_reflect="-1" x_reflect="-1" x_axis_rotation="1"/>
 </xacro:macro>
</robot>
